{"now": "2021/07/06 11:04:10 +0300", "version": "13.0.5", "plugin": "vim/800 vim-wakatime/8.0.0", "time": 1625558648.0, "level": "WARNING", "message": "{'ConnectionError': \"HTTPSConnectionPool(host='api.wakatime.com', port=443): Max retries exceeded with url: /api/v1/users/current/heartbeats.bulk (Caused by NewConnectionError('<urllib3.connection.VerifiedHTTPSConnection object at 0x7f5f538054c0>: Failed to establish a new connection: [Errno -3] Temporary failure in name resolution'))\", 'traceback': 'Traceback (most recent call last):\\n  File \"/home/catalin/.local/share/nvim/plugged/vim-wakatime/packages/wakatime/packages/urllib3/connection.py\", line 140, in _new_conn\\n    conn = connection.create_connection(\\n  File \"/home/catalin/.local/share/nvim/plugged/vim-wakatime/packages/wakatime/packages/urllib3/util/connection.py\", line 60, in create_connection\\n    for res in socket.getaddrinfo(host, port, family, socket.SOCK_STREAM):\\n  File \"/usr/lib/python3.9/socket.py\", line 953, in getaddrinfo\\n    for res in _socket.getaddrinfo(host, port, family, type, proto, flags):\\nsocket.gaierror: [Errno -3] Temporary failure in name resolution\\n\\nDuring handling of the above exception, another exception occurred:\\n\\nTraceback (most recent call last):\\n  File \"/home/catalin/.local/share/nvim/plugged/vim-wakatime/packages/wakatime/packages/urllib3/connectionpool.py\", line 598, in urlopen\\n    httplib_response = self._make_request(conn, method, url,\\n  File \"/home/catalin/.local/share/nvim/plugged/vim-wakatime/packages/wakatime/packages/urllib3/connectionpool.py\", line 346, in _make_request\\n    self._validate_conn(conn)\\n  File \"/home/catalin/.local/share/nvim/plugged/vim-wakatime/packages/wakatime/packages/urllib3/connectionpool.py\", line 850, in _validate_conn\\n    conn.connect()\\n  File \"/home/catalin/.local/share/nvim/plugged/vim-wakatime/packages/wakatime/packages/urllib3/connection.py\", line 284, in connect\\n    conn = self._new_conn()\\n  File \"/home/catalin/.local/share/nvim/plugged/vim-wakatime/packages/wakatime/packages/urllib3/connection.py\", line 149, in _new_conn\\n    raise NewConnectionError(\\nurllib3.exceptions.NewConnectionError: <urllib3.connection.VerifiedHTTPSConnection object at 0x7f5f538054c0>: Failed to establish a new connection: [Errno -3] Temporary failure in name resolution\\n\\nDuring handling of the above exception, another exception occurred:\\n\\nTraceback (most recent call last):\\n  File \"/home/catalin/.local/share/nvim/plugged/vim-wakatime/packages/wakatime/packages/requests/adapters.py\", line 430, in send\\n    resp = conn.urlopen(\\n  File \"/home/catalin/.local/share/nvim/plugged/vim-wakatime/packages/wakatime/packages/urllib3/connectionpool.py\", line 638, in urlopen\\n    retries = retries.increment(method, url, error=e, _pool=self,\\n  File \"/home/catalin/.local/share/nvim/plugged/vim-wakatime/packages/wakatime/packages/urllib3/util/retry.py\", line 388, in increment\\n    raise MaxRetryError(_pool, url, error or ResponseError(cause))\\nurllib3.exceptions.MaxRetryError: HTTPSConnectionPool(host=\\'api.wakatime.com\\', port=443): Max retries exceeded with url: /api/v1/users/current/heartbeats.bulk (Caused by NewConnectionError(\\'<urllib3.connection.VerifiedHTTPSConnection object at 0x7f5f538054c0>: Failed to establish a new connection: [Errno -3] Temporary failure in name resolution\\'))\\n\\nDuring handling of the above exception, another exception occurred:\\n\\nTraceback (most recent call last):\\n  File \"/home/catalin/.local/share/nvim/plugged/vim-wakatime/packages/wakatime/api.py\", line 111, in send_heartbeats\\n    response = session.post(api_url, data=request_body, headers=headers,\\n  File \"/home/catalin/.local/share/nvim/plugged/vim-wakatime/packages/wakatime/packages/requests/sessions.py\", line 555, in post\\n    return self.request(\\'POST\\', url, data=data, json=json, **kwargs)\\n  File \"/home/catalin/.local/share/nvim/plugged/vim-wakatime/packages/wakatime/packages/requests/sessions.py\", line 508, in request\\n    resp = self.send(prep, **send_kwargs)\\n  File \"/home/catalin/.local/share/nvim/plugged/vim-wakatime/packages/wakatime/packages/requests/sessions.py\", line 618, in send\\n    r = adapter.send(request, **kwargs)\\n  File \"/home/catalin/.local/share/nvim/plugged/vim-wakatime/packages/wakatime/packages/requests/adapters.py\", line 508, in send\\n    raise ConnectionError(e, request=request)\\nrequests.exceptions.ConnectionError: HTTPSConnectionPool(host=\\'api.wakatime.com\\', port=443): Max retries exceeded with url: /api/v1/users/current/heartbeats.bulk (Caused by NewConnectionError(\\'<urllib3.connection.VerifiedHTTPSConnection object at 0x7f5f538054c0>: Failed to establish a new connection: [Errno -3] Temporary failure in name resolution\\'))\\n'}"}
{"now": "2021/07/07 19:02:27 +0300", "version": "13.0.5", "plugin": "vim/800 vim-wakatime/8.0.0", "time": 1625673686.0, "level": "WARNING", "message": "{'ReadTimeout': \"HTTPSConnectionPool(host='api.wakatime.com', port=443): Read timed out. (read timeout=60)\", 'traceback': 'Traceback (most recent call last):\\n  File \"/home/catalin/.local/share/nvim/plugged/vim-wakatime/packages/wakatime/packages/urllib3/connectionpool.py\", line 387, in _make_request\\n    six.raise_from(e, None)\\n  File \"<string>\", line 2, in raise_from\\n  File \"/home/catalin/.local/share/nvim/plugged/vim-wakatime/packages/wakatime/packages/urllib3/connectionpool.py\", line 383, in _make_request\\n    httplib_response = conn.getresponse()\\n  File \"/usr/lib/python3.9/http/client.py\", line 1345, in getresponse\\n    response.begin()\\n  File \"/usr/lib/python3.9/http/client.py\", line 307, in begin\\n    version, status, reason = self._read_status()\\n  File \"/usr/lib/python3.9/http/client.py\", line 268, in _read_status\\n    line = str(self.fp.readline(_MAXLINE + 1), \"iso-8859-1\")\\n  File \"/usr/lib/python3.9/socket.py\", line 704, in readinto\\n    return self._sock.recv_into(b)\\n  File \"/usr/lib/python3.9/ssl.py\", line 1241, in recv_into\\n    return self.read(nbytes, buffer)\\n  File \"/usr/lib/python3.9/ssl.py\", line 1099, in read\\n    return self._sslobj.read(len, buffer)\\nsocket.timeout: The read operation timed out\\n\\nDuring handling of the above exception, another exception occurred:\\n\\nTraceback (most recent call last):\\n  File \"/home/catalin/.local/share/nvim/plugged/vim-wakatime/packages/wakatime/packages/requests/adapters.py\", line 430, in send\\n    resp = conn.urlopen(\\n  File \"/home/catalin/.local/share/nvim/plugged/vim-wakatime/packages/wakatime/packages/urllib3/connectionpool.py\", line 638, in urlopen\\n    retries = retries.increment(method, url, error=e, _pool=self,\\n  File \"/home/catalin/.local/share/nvim/plugged/vim-wakatime/packages/wakatime/packages/urllib3/util/retry.py\", line 357, in increment\\n    raise six.reraise(type(error), error, _stacktrace)\\n  File \"/home/catalin/.local/share/nvim/plugged/vim-wakatime/packages/wakatime/packages/urllib3/packages/six.py\", line 686, in reraise\\n    raise value\\n  File \"/home/catalin/.local/share/nvim/plugged/vim-wakatime/packages/wakatime/packages/urllib3/connectionpool.py\", line 598, in urlopen\\n    httplib_response = self._make_request(conn, method, url,\\n  File \"/home/catalin/.local/share/nvim/plugged/vim-wakatime/packages/wakatime/packages/urllib3/connectionpool.py\", line 389, in _make_request\\n    self._raise_timeout(err=e, url=url, timeout_value=read_timeout)\\n  File \"/home/catalin/.local/share/nvim/plugged/vim-wakatime/packages/wakatime/packages/urllib3/connectionpool.py\", line 309, in _raise_timeout\\n    raise ReadTimeoutError(self, url, \"Read timed out. (read timeout=%s)\" % timeout_value)\\nurllib3.exceptions.ReadTimeoutError: HTTPSConnectionPool(host=\\'api.wakatime.com\\', port=443): Read timed out. (read timeout=60)\\n\\nDuring handling of the above exception, another exception occurred:\\n\\nTraceback (most recent call last):\\n  File \"/home/catalin/.local/share/nvim/plugged/vim-wakatime/packages/wakatime/api.py\", line 111, in send_heartbeats\\n    response = session.post(api_url, data=request_body, headers=headers,\\n  File \"/home/catalin/.local/share/nvim/plugged/vim-wakatime/packages/wakatime/packages/requests/sessions.py\", line 555, in post\\n    return self.request(\\'POST\\', url, data=data, json=json, **kwargs)\\n  File \"/home/catalin/.local/share/nvim/plugged/vim-wakatime/packages/wakatime/packages/requests/sessions.py\", line 508, in request\\n    resp = self.send(prep, **send_kwargs)\\n  File \"/home/catalin/.local/share/nvim/plugged/vim-wakatime/packages/wakatime/packages/requests/sessions.py\", line 618, in send\\n    r = adapter.send(request, **kwargs)\\n  File \"/home/catalin/.local/share/nvim/plugged/vim-wakatime/packages/wakatime/packages/requests/adapters.py\", line 521, in send\\n    raise ReadTimeout(e, request=request)\\nrequests.exceptions.ReadTimeout: HTTPSConnectionPool(host=\\'api.wakatime.com\\', port=443): Read timed out. (read timeout=60)\\n'}"}
{"now": "2021/07/07 19:02:37 +0300", "version": "13.0.5", "plugin": "vim/800 vim-wakatime/8.0.0", "time": 1625673695.0, "level": "WARNING", "message": "{'ReadTimeout': \"HTTPSConnectionPool(host='api.wakatime.com', port=443): Read timed out. (read timeout=60)\", 'traceback': 'Traceback (most recent call last):\\n  File \"/home/catalin/.local/share/nvim/plugged/vim-wakatime/packages/wakatime/packages/urllib3/connectionpool.py\", line 387, in _make_request\\n    six.raise_from(e, None)\\n  File \"<string>\", line 2, in raise_from\\n  File \"/home/catalin/.local/share/nvim/plugged/vim-wakatime/packages/wakatime/packages/urllib3/connectionpool.py\", line 383, in _make_request\\n    httplib_response = conn.getresponse()\\n  File \"/usr/lib/python3.9/http/client.py\", line 1345, in getresponse\\n    response.begin()\\n  File \"/usr/lib/python3.9/http/client.py\", line 307, in begin\\n    version, status, reason = self._read_status()\\n  File \"/usr/lib/python3.9/http/client.py\", line 268, in _read_status\\n    line = str(self.fp.readline(_MAXLINE + 1), \"iso-8859-1\")\\n  File \"/usr/lib/python3.9/socket.py\", line 704, in readinto\\n    return self._sock.recv_into(b)\\n  File \"/usr/lib/python3.9/ssl.py\", line 1241, in recv_into\\n    return self.read(nbytes, buffer)\\n  File \"/usr/lib/python3.9/ssl.py\", line 1099, in read\\n    return self._sslobj.read(len, buffer)\\nsocket.timeout: The read operation timed out\\n\\nDuring handling of the above exception, another exception occurred:\\n\\nTraceback (most recent call last):\\n  File \"/home/catalin/.local/share/nvim/plugged/vim-wakatime/packages/wakatime/packages/requests/adapters.py\", line 430, in send\\n    resp = conn.urlopen(\\n  File \"/home/catalin/.local/share/nvim/plugged/vim-wakatime/packages/wakatime/packages/urllib3/connectionpool.py\", line 638, in urlopen\\n    retries = retries.increment(method, url, error=e, _pool=self,\\n  File \"/home/catalin/.local/share/nvim/plugged/vim-wakatime/packages/wakatime/packages/urllib3/util/retry.py\", line 357, in increment\\n    raise six.reraise(type(error), error, _stacktrace)\\n  File \"/home/catalin/.local/share/nvim/plugged/vim-wakatime/packages/wakatime/packages/urllib3/packages/six.py\", line 686, in reraise\\n    raise value\\n  File \"/home/catalin/.local/share/nvim/plugged/vim-wakatime/packages/wakatime/packages/urllib3/connectionpool.py\", line 598, in urlopen\\n    httplib_response = self._make_request(conn, method, url,\\n  File \"/home/catalin/.local/share/nvim/plugged/vim-wakatime/packages/wakatime/packages/urllib3/connectionpool.py\", line 389, in _make_request\\n    self._raise_timeout(err=e, url=url, timeout_value=read_timeout)\\n  File \"/home/catalin/.local/share/nvim/plugged/vim-wakatime/packages/wakatime/packages/urllib3/connectionpool.py\", line 309, in _raise_timeout\\n    raise ReadTimeoutError(self, url, \"Read timed out. (read timeout=%s)\" % timeout_value)\\nurllib3.exceptions.ReadTimeoutError: HTTPSConnectionPool(host=\\'api.wakatime.com\\', port=443): Read timed out. (read timeout=60)\\n\\nDuring handling of the above exception, another exception occurred:\\n\\nTraceback (most recent call last):\\n  File \"/home/catalin/.local/share/nvim/plugged/vim-wakatime/packages/wakatime/api.py\", line 111, in send_heartbeats\\n    response = session.post(api_url, data=request_body, headers=headers,\\n  File \"/home/catalin/.local/share/nvim/plugged/vim-wakatime/packages/wakatime/packages/requests/sessions.py\", line 555, in post\\n    return self.request(\\'POST\\', url, data=data, json=json, **kwargs)\\n  File \"/home/catalin/.local/share/nvim/plugged/vim-wakatime/packages/wakatime/packages/requests/sessions.py\", line 508, in request\\n    resp = self.send(prep, **send_kwargs)\\n  File \"/home/catalin/.local/share/nvim/plugged/vim-wakatime/packages/wakatime/packages/requests/sessions.py\", line 618, in send\\n    r = adapter.send(request, **kwargs)\\n  File \"/home/catalin/.local/share/nvim/plugged/vim-wakatime/packages/wakatime/packages/requests/adapters.py\", line 521, in send\\n    raise ReadTimeout(e, request=request)\\nrequests.exceptions.ReadTimeout: HTTPSConnectionPool(host=\\'api.wakatime.com\\', port=443): Read timed out. (read timeout=60)\\n'}"}
